Workbook

Sheet _Lookups
A1: Status | B1: YesNo | C1: ImageType | D1: Active
A2: Available | B2: Yes | C2: Main | D2: Yes
A3: Out of Stock | B3: No | C3: Gallery | D3: No
A4: Coming Soon | C4: Detail
A5: Hidden | C5: Lifestyle

Sheet Categories
A1: CategoryID | B1: CategoryName | C1: CategoryDescription | D1: CategoryImage | E1: DisplayOrder | F1: Active | G1: Featured | H1: SEOTitle | I1: SEODescription
A2: BC | B2: كراسي حلاقة وكوافير | C2: كراسي حلاقة رجالي و كراسى كوافير حريمى وصالونات تجميل بمواصفات احترافية | D2: /assets/categories/barber-chairs.webp | E2: 1 | F2: Yes | G2: Yes | H2: كراسي حلاقة وكوافير | مصنع أولاد يحيى | I2: أفضل تشكيلة كراسي حلاقة هيدروليك وكوافير في مصر من مصنع أولاد يحيى بتصنيع عالي الجودة, كراسى حلاقه لوكس و ثابت و كراسى باكم.
A3: KC | B3: كراسي أطفال | C3: كراسي حلاقة مخصصة للأطفال بتصميمات جذابة وآمنة | D3: /assets/categories/kids-chairs.webp | E3: 2 | F3: Yes | G3: No | H3: كراسي حلاقة أطفال | مصنع أولاد يحيى | I3: تشكيلة كراسي حلاقة أطفال بأمان تام وتصميمات تناسب صالونات الحلاقة.
A4: SH | B4: أحواض غسيل الشعر | C4: أحواض غسيل شعر وسيراميك متين لصالونات التجميل والحلاقة | D4: /assets/categories/shampoo-units.webp | E4: 3 | F4: Yes | G4: Yes | H4: أحواض غسيل شعر وصالونات | أولاد يحيى | I4: وحدات غسيل شعر متكاملة مع احواض بورسلين وخامات مقاومة للمياه.
A5: CH | B5: شيزلونجات | C5: شيزلونجات مساج وتنظيف بشرة متعددة الاستخدامات | D5: /assets/categories/chaise-lounges.webp | E5: 4 | F5: Yes | G5: No | H5: شيزلونجات صالونات ومراكز تجميل | أولاد يحيى | I5: شيزلونجات احترافية لصالونات التجميل ومراكز العناية.
A6: EQ | B6: مستلزمات وتجهيزات الصالونات | C6: تجهيزات ومعدات متكاملة لافتتاح وتجديد صالونات الحلاقة | D6: /assets/categories/equipment.webp | E6: 5 | F6: Yes | G6: No | H6: تجهيزات ومعدات صالونات حلاقة | أولاد يحيى | I6: كافة مستلزمات وتجهيزات صالونات الحلاقة ومراكز التجميل من المصنع مباشرة.

Sheet Products
A1: ProductID | B1: ProductCode | C1: ProductName | D1: CategoryID | E1: CategoryName | F1: ShortDescription | G1: FullDescription | H1: ProductStatus | I1: Featured | J1: DisplayOrder | K1: Price | L1: ShowPrice | M1: MainImage | N1: Image2 | O1: Image3 | P1: Image4 | Q1: Image5 | R1: Specifications | S1: Materials | T1: AvailableColors | U1: CustomizationAvailable | V1: WhatsAppMessage | W1: SEOTitle | X1: SEODescription | Y1: Keywords | Z1: CreatedDate | AA1: LastUpdated
A2: BC-001 | B2: AY-01 | C2: كرسى ثابت عادى | D2: BC | E2: =IFERROR(VLOOKUP(D2, Categories!A:B, 2, FALSE), "") -> كراسي حلاقة وكوافير | F2: الكرسى الدبابه الثابت , خامات قويه و يعيش سنين, مناسب لصالونات الحلاقة الرجالي. | G2: كرسي حلاقة رجالي , الكرسى الدبابه صُمم خصيصًا ليتحمل ضغط الشغل الشاق والمستمر داخل الصالونات المزدحمة. يعتمد الكرسي على شاسيه حديد متين وقاعدة ثابتة تمنحه أقصى درجات الاتزان والأمان أثناء العمل اليومي، مع خامات عالية الجودة تضمن بقاءه لسنوات طويلة دون تأثر. مزود بتنجيد مريح وفوم كثيف لتوفير راحة مثالية للزبون أثناء جلسات الحلاقة الطويلة، ليكون الاستثمار الأضمن والعملي لكل صاحب صالون يبحث عن القوة والاعتمادية دون قلق من الأعطال. | H2: Available | I2: No | J2: 11 | K2: 2650 | L2: Yes | M2: D:\website\website\assets\products\BC-01\main.webp | S2: شاسيه حديد معالج، جلد صناعي عالي التحمل، فوم كثافة عالية | T2: أسود، بني، جملي | U2: Yes | V2: ="مرحبًا، أود الاستفسار عن كود المنتج: " & B2 & " (" & C2 & ") المعروض على موقعكم." -> مرحبًا، أود الاستفسار عن كود المنتج: AY-01 (كرسى ثابت عادى) المعروض على موقعكم. | W2: كرسي حلاقة كلاسيك هيدروليك | مصنع أولاد يحيى | X2: احصل على كرسي حلاقة كلاسيك هيدروليك من مصنع أولاد يحيى. متانة عالية وتصميم مريح. | Y2: كرسي حلاقة, كراسي صالونات, كراسي هيدروليك, أولاد يحيى | Z2: 2026-09-20 | AA2: 2026-09-20
A3: BC-002 | B3: AY-02 | C3: كرسى لوكس دواسه عريضه | D3: BC | E3: =IFERROR(VLOOKUP(D3, Categories!A:B, 2, FALSE), "") -> كراسي حلاقة وكوافير | F3: كرسى لوكس دواسه عريضه - كرسى عملى و اقتصادى | G3: كرسي حلاقة رجالي , الكرسى اللوكس , صُمم خصيصًا ليتحمل ضغط الشغل الشاق والمستمر داخل الصالونات المزدحمة. يعتمد الكرسي على شاسيه حديد متين وقاعدة ثابتة تمنحه أقصى درجات الاتزان والأمان أثناء العمل اليومي، مع خامات عالية الجودة تضمن بقاءه لسنوات طويلة دون تأثر. مزود بتنجيد مريح وفوم كثيف لتوفير راحة مثالية للزبون أثناء جلسات الحلاقة الطويلة، ليكون الاستثمار الأضمن والعملي لكل صاحب صالون يبحث عن القوة والاعتمادية دون قلق من الأعطال. | H3: Available | I3: No | J3: 12 | K3: 2900 | L3: Yes | M3: D:\website\website\assets\products\BC-02\main.webp | S3: جلد فاخر، قاعدة نيكل كروم | T3: أسود، رمادي، بيج | U3: Yes | V3: ="مرحبًا، أود الاستفسار عن كود المنتج: " & B3 & " (" & C3 & ") المعروض على موقعكم." -> مرحبًا، أود الاستفسار عن كود المنتج: AY-02 (كرسى لوكس دواسه عريضه) المعروض على موقعكم. | W3: كرسي كوافير عصري | مصنع أولاد يحيى | X3: كرسي كوافير وصالونات تجميل بتصميم حديث وجودة تصنيع مصرية فائقة. | Y3: كرسي كوافير, كراسي تجميل, صالونات حريمي | Z3: 2026-09-20 | AA3: 2026-09-20
A4: BC-003 | B4: AY-025 | C4: شبك ذهبى | D4: BC | E4: =IFERROR(VLOOKUP(D4, Categories!A:B, 2, FALSE), "") -> كراسي حلاقة وكوافير | F4: كرسي حريمي موديل "الشبك" – لمسة شياكة وفخامة لصالونك من مصنع أولاد يحيى! كرسي كوافير بتصميم عصري راقي مع طلاء PVD دهبي فخم وعالي الجودة، مزود بهيدروليك قوي وسلس، وتنجيد إسفنج عالي الكثافة مع جلد متين سهل التنظيف وضد التقشير ليتحمل ضغط الشغل اليومي ويدوم معاك سنين. | G4: كرسي كوافير حريمي موديل "الشبك" الدهبي | مصنع أولاد يحيى لتصنيع كراسي الحلاقة لو بتدوري/بتدور على قطعة تجمع بين الشياكة المطلقة والعملية والتحمل، كرسي "الشبك" هو الاختيار المثالي اللي هيضيف لمسة ديكور فاخرة لأي بيوتي سنتر أو صالون حريمي. أهم مميزات ومواصفات الكرسي: تصميم عصري مميز: ظهر بتصميم شبكي أنيق ومودرن مع خياطة كابوتنيه راقية على المقعد والمسند بتدي شكل شيك جداً ومريح في نفس الوقت. طلاء دهبي PVD عالي الجودة: معالج بالكامل ضد الصدأ والخدوش ومقاوم للرطوبة والمواد الكيماوية عشان يفضل محتفظ بلمعته ورونقه على المدى الطويل. هيدروليك قوي وسلس: بيتحمل الأوزان الثقيلة وبيديك تحكم مرن في الرفع والنزول بكل سهولة أثناء الشغل. تنجيد وإسفنج عالي الكثافة: مريح جداً للزبونة في الجلسات الطويلة، ومبيبطش ولا يغير شكله مع كثرة الاستخدام. جلد ممتاز وفاخر: خامة متينة جداً، ضد التقشير وسهل التنظيف والتعقيم بعد كل عميلة بدون ما يتأثر. قاعدة متزنة وثابتة: صينية دائرية دهبية واسعة تضمن ثبات الكرسي 100% مع مسند مريح للقدمين. | H4: Available | I4: Yes | J4: 5 | K4: 6000 | L4: Yes | M4: D:\website\website\assets\products\BC-03\main.webp | N4: D:\website\website\assets\products\BC-03\angle-1.jpg | R4: مضخة هيدروليك دائرية، دوران 360 درجة، إمالة حتى 135 درجة | T4: أسود، بني، جملي, اوف وايت, كشمير | U4: Yes | W4: كرسي كوافير حريمي هيدروليك موديل الشبك دهبي PVD | مصنع أولاد يحيى | X4: احصل على كرسي كوافير حريمي موديل الشبك هيدروليك من مصنع أولاد يحيى، طلاء PVD دهبي فاخر عالي الجودة ضد الصدأ، إسفنج عالي الكثافة وجلد متين سهل التنظيف وضد التقشير بأفضل سعر. | Y4: كرسي كوافير، كرسي كوافير حريمي، كرسي الشبك، كراسي صالونات تجميل، كراسي بيوتي سنتر، كرسي هيدروليك دهبي، طلاء PVD، مصنع أولاد يحيى، لوازم كوافير، تجهيز صالونات حريمي | Z4: 2026-09-20 | AA4: 2026-09-20
A5: BC-004 | B5: AY-03 | C5: كرسى دبابه ثابت دواسه كوتش | D5: BC | E5: =IFERROR(VLOOKUP(D5, Categories!A:B, 2, FALSE), "") -> كراسي حلاقة وكوافير | H5: Hidden | K5: 3400 | L5: Yes | Z5: 2026-09-20 | AA5: 2026-09-20
A6: BC-005 | B6: AY-04 | C6: كرسى دبابه بيلف دواسه كوتش | D6: BC | E6: =IFERROR(VLOOKUP(D6, Categories!A:B, 2, FALSE), "") -> كراسي حلاقة وكوافير | H6: Hidden | K6: 3650 | L6: Yes | Z6: 2026-09-20 | AA6: 2026-09-20
A7: BC-006 | B7: AY-05 | C7: كرسى لوكس دواسه كوتش ثابت | D7: BC | E7: =IFERROR(VLOOKUP(D7, Categories!A:B, 2, FALSE), "") -> كراسي حلاقة وكوافير | H7: Hidden | K7: 3500 | L7: Yes | Z7: 2026-09-20 | AA7: 2026-09-20
A8: BC-007 | B8: AY-06 | C8: دبابه فك وتركيب بالكامل دواسه كاوتش | D8: BC | E8: =IFERROR(VLOOKUP(D8, Categories!A:B, 2, FALSE), "") -> كراسي حلاقة وكوافير | H8: Hidden | K8: 3700 | L8: Yes | Z8: 2026-09-20 | AA8: 2026-09-20
A9: BC-008 | B9: AY-07 | C9: تفاحه دواسه معدن | D9: BC | E9: =IFERROR(VLOOKUP(D9, Categories!A:B, 2, FALSE), "") -> كراسي حلاقة وكوافير | H9: Hidden | K9: 5400 | L9: Yes | Z9: 2026-09-20 | AA9: 2026-09-20
A10: BC-009 | B10: AY-08 | C10: كرسى تفاحه دواسه كاوتش | D10: BC | E10: =IFERROR(VLOOKUP(D10, Categories!A:B, 2, FALSE), "") -> كراسي حلاقة وكوافير | F10: كرسي حلاقة رجالي موديل "التفاحة" – الراحة والقوة اللي صالونك محتاجها من مصنع أولاد يحيى! كرسي مصمم خصيصاً ليتحمل أقصى درجات ضغط الشغل اليومي، مزود بهيدروليك قوي وسلس، وإمكانية إمالة الظهر ومسند رأس متحرك لجلسات حلاقة وتنظيف بشرة مريحة جداً لزبونك، مع تنجيد إسفنج عالي الكثافة وجلد مستورد متين ومقاوم للتقشير. | G10: كرسي حلاقة رجالي هيدروليك موديل "التفاحة" | تصنيع مصنع أولاد يحيى لكراسي الحلاقة لو بتجهز صالون حلاقة رجالي وبتبحث عن المتانة والعملية والراحة الفائقة، موديل "التفاحة" هو خيارك الأنسب والأكثر اعتمادية؛ تصميم مريح ومدروس يدعم ظهر الزبون ويديك حرية وسهولة كاملة أثناء الشغل. أهم مواصفات ومميزات الموديل: هيدروليك فائق التحمل: بستم هيدروليك قوي ناعم في الحركة وسهل الرفع والنزول بدون أي مجهود، مع دوران 360 درجة وثبات تام. إمالة الظهر وتعدد الأوضاع: إمكانية نزول الظهر بزاوية مريحة جداً لخدمات الدقن، الفتلة، وماسكات تنظيف البشرة. مسند رأس متحرك (مخدة): قابلة للتعديل والرفع والنزول لتناسب كل أطوال الزبائن وتوفير أقصى درجات الراحة للرقبة. تنجيد وإسفنج صب عالي الكثافة: إسفنج مريح وعملي يحتفظ بمرونته وارتفاعه ومبيبطش مع كثرة الاستخدام والسنوات. جلد صناعي عالي الجودة: خامة ممتازة مقاومة للتشقق والتقشير، سهلة المسح والتعقيم المستمر ومقاومة للمياه والمواد المستخدمة في الصالون. قاعدة حديد مدعمة بالكروم: صينية دائرية ثقيلة تضمن اتزان الكرسي التام وعدم اهتزازه مع مسند قدم قوي ومريح. 📞 للحجز والاستفسار وطلب الأوردر مباشرة: تواصل معنا عبر الهاتف أو واتساب: 201008355616+ 🌐 لمشاهدة أحدث موديلاتنا وتحميل الكتالوج بالكامل: https://wa.me/c/201064116703 📲 صفحتنا الرسمية على فيسبوك: https://www.facebook.com/YahiaSonsCosmetics 📢 تابع عروضنا وخامات المصنع على التليجرام: https://t.me/YahiaSons | H10: Available | I10: Yes | J10: 6 | K10: 5500 | L10: Yes | M10: D:\website\website\assets\products\BC-09\main.webp | R10: هيدروليك رفع وخفض سلس، دوران 360 درجة، إمكانية إمالة الظهر لمستويات متعددة، مسند رأس متحرك وقابل للتعديل، مسند قدم متين ومريح | S10: شاسيه حديد متين عالي التحمل، قاعدة دائرية كروم ثقيلة مضادة للانزلاق، جلد مستورد فاخر ضد التقشير وسهل التنظيف، إسفنج سوفت عالي الكثافة | T10: أسود، بني، جملي, اوف وايت, كشمير | U10: Yes | V10: مرحباً، أود الاستفسار عن رسى التفاحه (كرسي حلاقة رجالي موديل التفاحة هيدروليك) المعروض على موقعكم. | W10: كرسي حلاقة رجالي هيدروليك موديل التفاحة | مصنع أولاد يحيى | X10: اشتري كرسي حلاقة رجالي موديل التفاحة هيدروليك من مصنع أولاد يحيى، شاسيه حديد قوي، إمالة ظهر ومسند رأس متحرك، إسفنج عالي الكثافة وجلد فاخر يتحمل ضغط الشغل بأفضل سعر مصنع. | Y10: كرسي حلاقة، كرسي حلاقة رجالي، كرسي التفاحة، كراسي صالونات حلاقة، كرسي هيدروليك، مصنع أولاد يحيى، تجهيز صالونات رجالي، كراسي حلاقة هيدروليك، لوازم كوافير وحلاقة | Z10: 2026-09-20 | AA10: 2026-09-20
A11: BC-010 | B11: AY-09 | C11: تمساح دواسه معدن | D11: BC | E11: =IFERROR(VLOOKUP(D11, Categories!A:B, 2, FALSE), "") -> كراسي حلاقة وكوافير | J11: 7 | K11: 5400 | L11: Yes | M11: D:\website\website\assets\products\BC-010\main.webp | Z11: 2026-09-20 | AA11: 2026-09-20
A12: BC-011 | B12: AY-11 | C12: كريستال دواسه معدن | D12: BC | E12: =IFERROR(VLOOKUP(D12, Categories!A:B, 2, FALSE), "") -> كراسي حلاقة وكوافير | H12: Hidden | K12: 5800 | L12: Yes | Z12: 2026-09-20 | AA12: 2026-09-20
A13: BC-012 | B13: AY-12 | C13: كريستال دواسه كوتش | D13: BC | E13: =IFERROR(VLOOKUP(D13, Categories!A:B, 2, FALSE), "") -> كراسي حلاقة وكوافير | J13: 8 | K13: 5900 | L13: Yes | M13: D:\website\website\assets\products\BC-012\main.webp | Z13: 2026-09-20 | AA13: 2026-09-20
A14: BC-013 | B14: AY-13 | C14: كرسي رويال هيدروليك مدور (Royal Round) ذهبى | D14: BC | E14: =IFERROR(VLOOKUP(D14, Categories!A:B, 2, FALSE), "") -> كراسي حلاقة وكوافير | J14: 9 | K14: 7200 | L14: Yes | M14: D:\website\website\assets\products\BC-013\main.webp | Z14: 2026-09-20 | AA14: 2026-09-20
A15: BC-014 | B15: AY-13B | C15: كرسي رويال هيدروليك مدور (Royal Round) فضى | D15: BC | E15: =IFERROR(VLOOKUP(D15, Categories!A:B, 2, FALSE), "") -> كراسي حلاقة وكوافير | J15: 10 | K15: 6900 | L15: Yes | M15: D:\website\website\assets\products\BC-014\main.webp | Z15: 2026-09-20 | AA15: 2026-09-20
A16: BC-016 | B16: AY-14 | C16: موزه باكم كبير ذهبى | D16: BC | E16: =IFERROR(VLOOKUP(D16, Categories!A:B, 2, FALSE), "") -> كراسي حلاقة وكوافير | J16: 13 | K16: 6500 | L16: Yes | M16: D:\website\website\assets\products\BC-016\main.webp | Z16: 2026-09-20 | AA16: 2026-09-20
A17: BC-017 | B17: AY-14C | C17: كرسى موزه | D17: BC | E17: =IFERROR(VLOOKUP(D17, Categories!A:B, 2, FALSE), "") -> كراسي حلاقة وكوافير | H17: Hidden | K17: 6000 | L17: Yes | Z17: 2026-09-20 | AA17: 2026-09-20
A18: BC-018 | B18: AY-15 | C18: موزه حريمى ذهبى | D18: BC | E18: =IFERROR(VLOOKUP(D18, Categories!A:B, 2, FALSE), "") -> كراسي حلاقة وكوافير | I18: Yes | J18: 16 | K18: 5900 | L18: Yes | M18: D:\website\website\assets\products\BC-018\main.webp | Z18: 2026-09-20 | AA18: 2026-09-20
A19: BC-019 | B19: AY-16 | C19: موزه باكم كبير فضى | D19: BC | E19: =IFERROR(VLOOKUP(D19, Categories!A:B, 2, FALSE), "") -> كراسي حلاقة وكوافير | J19: 14 | K19: 6000 | L19: Yes | M19: D:\website\website\assets\products\BC-019\main.webp | Z19: 2026-09-20 | AA19: 2026-09-20
A20: BC-020 | B20: AY-17 | C20: موزه حريمى فضى | D20: BC | E20: =IFERROR(VLOOKUP(D20, Categories!A:B, 2, FALSE), "") -> كراسي حلاقة وكوافير | J20: 15 | K20: 5500 | L20: Yes | M20: D:\website\website\assets\products\BC-020\main.webp | N20: D:\website\website\assets\products\BC-012\angle-1.jpg | Z20: 2026-09-20 | AA20: 2026-09-20
A21: BC-021 | B21: AY-19 | C21: مربع يد استانليس باكم حريمى فضى | D21: BC | E21: =IFERROR(VLOOKUP(D21, Categories!A:B, 2, FALSE), "") -> كراسي حلاقة وكوافير | J21: 17 | K21: 5500 | L21: Yes | M21: D:\website\website\assets\products\BC-021\main.webp | Z21: 2026-09-20 | AA21: 2026-09-20
A22: BC-022 | B22: AY-20 | C22: مربع يد استانليس باكم كبير فضى | D22: BC | E22: =IFERROR(VLOOKUP(D22, Categories!A:B, 2, FALSE), "") -> كراسي حلاقة وكوافير | J22: 18 | K22: 6000 | L22: Yes | M22: D:\website\website\assets\products\BC-022\main.webp | Z22: 2026-09-20 | AA22: 2026-09-20
A23: BC-023 | B23: AY-21 | C23: مربع يد استانليس باكم حريمى ذهبى | D23: BC | E23: =IFERROR(VLOOKUP(D23, Categories!A:B, 2, FALSE), "") -> كراسي حلاقة وكوافير | J23: 21 | K23: 5900 | L23: Yes | M23: D:\website\website\assets\products\BC-023\main.webp | N23: D:\website\website\assets\products\BC-023\detail.jpg | O23: D:\website\website\assets\products\BC-023\angle-1.jpg | Z23: 2026-09-20 | AA23: 2026-09-20
A24: BC-024 | B24: AY-22 | C24: مربع يد استالنليس باكم كبير ذهبى | D24: BC | E24: =IFERROR(VLOOKUP(D24, Categories!A:B, 2, FALSE), "") -> كراسي حلاقة وكوافير | J24: 22 | K24: 6400 | L24: Yes | M24: D:\website\website\assets\products\BC-024\main.webp | N24: D:\website\website\assets\products\BC-024\angle-1.jpg | Z24: 2026-09-20 | AA24: 2026-09-20
A25: BC-025 | B25: AY-23 | C25: مربع اقتصادى فضى اسود | D25: BC | E25: =IFERROR(VLOOKUP(D25, Categories!A:B, 2, FALSE), "") -> كراسي حلاقة وكوافير | J25: 19 | K25: 3900 | L25: Yes | M25: D:\website\website\assets\products\BC-025\main.webp | N25: D:\website\website\assets\products\BC-025\angle-1.jpg | Z25: 2026-09-20 | AA25: 2026-09-20
A26: BC-026 | B26: AY-23B | C26: مربع اقتصادى فضى جلد مختلف | D26: BC | E26: =IFERROR(VLOOKUP(D26, Categories!A:B, 2, FALSE), "") -> كراسي حلاقة وكوافير | I26: Yes | J26: 20 | K26: 4000 | L26: Yes | M26: D:\website\website\assets\products\BC-026\main.webp | Z26: 2026-09-20 | AA26: 2026-09-20
A27: BC-028 | B27: AY-23GOLD | C27: مربع اقتصادى ذهبى | D27: BC | E27: =IFERROR(VLOOKUP(D27, Categories!A:B, 2, FALSE), "") -> كراسي حلاقة وكوافير | I27: Yes | J27: 23 | K27: 4100 | L27: Yes | M27: D:\website\website\assets\products\BC-028\main.webp | Z27: 2026-09-20 | AA27: 2026-09-20
A28: BC-029 | B28: AY-26 | C28: ملكى مصرى كبير استانليس بالكامل فضى | D28: BC | E28: =IFERROR(VLOOKUP(D28, Categories!A:B, 2, FALSE), "") -> كراسي حلاقة وكوافير | I28: Yes | J28: 4 | K28: 11000 | L28: Yes | M28: D:\website\website\assets\products\BC-029\main.webp | Z28: 2026-09-20 | AA28: 2026-09-20
A29: BC-030 | B29: AY-27 | C29: ملكى مصرى كبير استانليس بالكامل ذهبى | D29: BC | E29: =IFERROR(VLOOKUP(D29, Categories!A:B, 2, FALSE), "") -> كراسي حلاقة وكوافير | J29: 2 | K29: 12000 | L29: Yes | M29: D:\website\website\assets\products\BC-030\main.webp | Z29: 2026-09-20 | AA29: 2026-09-20
A30: BC-031 | B30: AY-28 | C30: ملكى حديث فضى | D30: BC | E30: =IFERROR(VLOOKUP(D30, Categories!A:B, 2, FALSE), "") -> كراسي حلاقة وكوافير | H30: Available | I30: Yes | J30: 1 | K30: 9000 | L30: Yes | M30: D:\website\website\assets\products\BC-031\main.webp | N30: D:\website\website\assets\products\BC-031\angle-1.jpg | O30: D:\website\website\assets\products\BC-031\angle-2.jpg | R30: مضخة هيدروليك دائرية قوية، دوران 360 درجة، نظام إمالة ظهر هيدروليكي متعدد المستويات، مسند رأس قابل للتعديل والفك، مسند أرجل متين مدعم بكاوتش مانع للانزلاق | S30: شاسيه حديد ثقيل معالج عالي الصلابة، إكسسوارات وقاعدة صينية نيكل كروم ثقيلة ، فوم وإسفنج كابوتنيه عالي الكثافة، جلد فاخر مستورد معالج ضد التقشير والتشقق | V30: مرحباً، أود الاستفسار عن كود المنتج: AY-05 (الكرسي الملكي المصري الكلاسيك هيدروليك) المعروض على موقعكم. | W30: كرسي حلاقة رجالي كلاسيك الملكي المصري هيدروليك | مصنع أولاد يحيى | X30: اكتشف الكرسي الملكي المصري الكلاسيك من مصنع أولاد يحيى، تصميم بريميوم يجمع بين فخامة الكلاسيك وقوة التحمل، هيدروليك عالي الجودة ينافس المستورد وبأفضل سعر مصنع في مصر. | Y30: كرسي حلاقة كلاسيك، الكرسي الملكي المصري، كراسي حلاقة رجالي، كرسي حلاقة هيدروليك، مصنع أولاد يحيى، تجهيز صالونات حلاقة، كراسي باربر شوب، كراسي حلاقة مستوردة ومحلية | Z30: 2026-09-20 | AA30: 2026-09-20
A31: BC-032 | B31: AY-29 | C31: ملكى حديث ذهبى | D31: BC | E31: =IFERROR(VLOOKUP(D31, Categories!A:B, 2, FALSE), "") -> كراسي حلاقة وكوافير | I31: Yes | J31: 3 | K31: 1000 | L31: Yes | M31: D:\website\website\assets\products\BC-032\main.webp | N31: D:\website\website\assets\products\BC-032\angle-1.jpg | O31: D:\website\website\assets\products\BC-032\angle-2.jpg | Z31: 2026-09-20 | AA31: 2026-09-20
A32: BC-033 | B32: AY-34 | C32: كرسى الورده | D32: BC | E32: =IFERROR(VLOOKUP(D32, Categories!A:B, 2, FALSE), "") -> كراسي حلاقة وكوافير | I32: Yes | J32: 24 | K32: 4400 | L32: Yes | M32: D:\website\website\assets\products\BC-033\main.webp | Z32: 2026-09-20 | AA32: 2026-09-20
A33: BC-034 | B33: AY-35 | C33: كرسى الفنجان | D33: BC | E33: =IFERROR(VLOOKUP(D33, Categories!A:B, 2, FALSE), "") -> كراسي حلاقة وكوافير | I33: Yes | J33: 25 | K33: 4500 | L33: Yes | M33: D:\website\website\assets\products\BC-034\main.webp | N33: D:\website\website\assets\products\BC-034\angle-1.jpg | Z33: 2026-09-20 | AA33: 2026-09-20
A34: CH-01 | B34: AY-B1 | C34: شازلونج | D34: CH | E34: =IFERROR(VLOOKUP(D34, Categories!A:B, 2, FALSE), "") -> شيزلونجات | J34: 26 | K34: 3300 | L34: Yes | M34: D:\website\website\assets\products\CH-01\main.webp | Z34: 2026-09-20 | AA34: 2026-09-20
A35: CH-02 | B35: AY-C01 | C35: كرسى قاعده نجمه للشازلونج | D35: CH | E35: =IFERROR(VLOOKUP(D35, Categories!A:B, 2, FALSE), "") -> شيزلونجات | J35: 27 | K35: 1500 | L35: Yes | M35: D:\website\website\assets\products\CH-02\main.webp | N35: D:\website\website\assets\products\CH-02\angle-1.jpg | Z35: 2026-09-20 | AA35: 2026-09-20
A36: BC-035 | B36: AY-LUX30 | C36: ملكى حديث | D36: BC | E36: =IFERROR(VLOOKUP(D36, Categories!A:B, 2, FALSE), "") -> كراسي حلاقة وكوافير | F36: الكرسي الملكي المصري الكلاسيك – الفخامة البريميوم اللي حققت المعادلة الصعبة من مصنع أولاد يحيى! تحفة فنية بتصميم كلاسيكي ملكي يضيف هيبة وأناقة لأي باربر شوب؛ جودة تصنيع ومتانة تفوق المستورد، مزود ببستم هيدروليك سلس، إمالة ظهر كاملة لخدمات الدقن والتنظيف، وتنجيد كابوتنيه بإسفنج عالي الكثافة وجلد متين ضد التقشير بأعلى قيمة مقابل أفضل سعر. | G36: الكرسي الملكي المصري الكلاسيك | مصنع أولاد يحيى لتصنيع كراسي الحلاقة الموديل اللي أثبت كفاءته وحقق المعادلة الصعبة: فخامة المظهر + قوة التحمل + سعر المصنع المباشر. صُمم الكرسي الملكي ليوفر تجربة حلاقة استثنائية من الدرجة الأولى لزبونك مع سهولة وتحكم كامل للحلاق أثناء ساعات العمل الطويلة. أهم مواصفات ومميزات الموديل الملكي: تصميم كلاسيكي ملكي (Premium Look): ظهر دائري أنيق وتطريز كابوتنيه ملوكي غائر يمنح الصالون طابع الفخامة والرقي، متوفر بألوان كلاسيكية متعددة (أسود مط، هافان، نبيتي معتق، بيج). هيدروليك فائق الاعتمادية: بستم رفع وخفض ناعم وقوي جداً يتحمل الأوزان الثقيلة مع دوران كامل 360 درجة وثبات تام. إمالة مرنة للظهر: ذراع تحكم جانبي يتيح نزول الظهر بزاوية استلقاء مريحة ومثالية لجلسات الدقن، الفتلة، والماسك وتنظيف البشرة. مسند رأس مريح: مخدة رأس قابلة للرفع، التنزيل، أو الفك تماماً حسب طول العميل وراحة الرقبة. تنجيد وإسفنج عالي الكثافة: إسفنج صب متين لا يهبط بمرور الوقت ويوفر راحة تدوم طوال فترة الجلسة. جلد مستورد ضد التقشير: خامة جلد ممتازة شديدة التحمل ومقاومة للاحتكاك وسهلة التنظيف والتعقيم اليومي. قاعدة صينية متزنة: قاعدة دائرية ثقيلة تمنع أي اهتزاز أثناء الشغل مع دعامات كاوتش سفلية لحماية الأرضيات ومنع الانزلاق. 📞 للحجز والاستفسار وطلب الأوردر: تواصل معنا مباشرة عبر الهاتف أو واتساب: 201008355616+ 🌐 لمشاهدة باقي موديلات المصنع والكتالوج بالكامل: https://wa.me/c/201064116703 📲 تابعونا على صفحة الفيسبوك: https://www.facebook.com/YahiaSonsCosmetics 📢 قناتنا الرسمية على التليجرام: https://t.me/YahiaSons | H36: Available | K36: 8700 | L36: Yes | Z36: 2026-09-20 | AA36: 2026-09-20
A37: BC-036 | B37: AY-LUX31 | C37: طياره بنتلى | D37: BC | E37: =IFERROR(VLOOKUP(D37, Categories!A:B, 2, FALSE), "") -> كراسي حلاقة وكوافير | J37: 28 | K37: 11000 | L37: Yes | M37: D:\website\website\assets\products\BC-036\main.webp | Z37: 2026-09-20 | AA37: 2026-09-20
A38: CH-03 | B38: AY-P01 | C38: كرسى بدكير بالبف | D38: CH | E38: =IFERROR(VLOOKUP(D38, Categories!A:B, 2, FALSE), "") -> شيزلونجات | J38: 29 | K38: 5500 | L38: Yes | M38: D:\website\website\assets\products\CH-03\main.webp | Z38: 2026-09-20 | AA38: 2026-09-20
A39: SH-01 | B39: AY-W01 | C39: حوض غسيل شعبى | D39: SH | E39: =IFERROR(VLOOKUP(D39, Categories!A:B, 2, FALSE), "") -> أحواض غسيل الشعر | J39: 33 | K39: 2300 | L39: Yes | M39: D:\website\website\assets\products\SH-01\main.webp | Z39: 2026-09-20 | AA39: 2026-09-20
A40: SH-02 | B40: AY-W02 | C40: حوض غسيل بورسلين ذهبى | D40: SH | E40: =IFERROR(VLOOKUP(D40, Categories!A:B, 2, FALSE), "") -> أحواض غسيل الشعر | J40: 30 | K40: 7000 | L40: Yes | M40: D:\website\website\assets\products\SH-02\main.webp | Z40: 2026-09-20 | AA40: 2026-09-20
...

Sheet ProductSpecs
A1: ProductID | B1: SpecificationName | C1: SpecificationValue | D1: DisplayOrder
A2: BC-001 | B2: نوع المضخة | C2: هيدروليك زيت ثقيل | D2: 1
A3: BC-001 | B3: زاوية الدوران | C3: 360 درجة مع قفل أمان | D3: 2
A4: BC-001 | B4: زاوية إمالة الظهر | C4: تصل إلى 135 درجة | D4: 3
A5: BC-001 | B5: خامة القاعدة | C5: قاعدة دائرية ستانلس ستيل / نيكل كروم | D5: 4
A6: BC-001 | B6: خامة التنجيد | C6: جلد صناعي معالج ضد السوائل والحرارة | D6: 5
A7: BC-001 | B7: كثافة الفوم | C7: سفنج مضغوط عالي الكثافة (Soft/High Density) | D7: 6
A8: BC-002 | B8: نوع المضخة | C8: هيدروليك مع قاعدة نجمية | D8: 1
A9: BC-002 | B9: أقصى حمولة | C9: 180 كجم | D9: 2
A10: KC-001 | B10: وسائل الأمان | C10: حزام أمان ثلاثي النقاط للأطفال | D10: 1
A11: KC-001 | B11: مصدر الطاقة للأصوات | C11: بطارية قابلة لإعادة الشحن | D11: 2

Sheet ProductImages
A1: ImageID | B1: ProductID | C1: ImageType | D1: ImagePath | E1: AltText | F1: DisplayOrder | G1: Active
A2: IMG-001 | B2: BC-001 | C2: Main | D2: /assets/products/barber-salon/BC-001/main.webp | E2: كرسي حلاقة كلاسيك هيدروليك - المنظر الأمامي | F2: 1 | G2: Yes
A3: IMG-002 | B3: BC-001 | C3: Gallery | D3: /assets/products/barber-salon/BC-001/angle-1.webp | E3: كرسي حلاقة كلاسيك بزاوية جانبية مائلة | F3: 2 | G3: Yes
A4: IMG-003 | B4: BC-001 | C4: Detail | D4: /assets/products/barber-salon/BC-001/angle-2.webp | E4: تفاصيل تنجيد المقعد والظهر وقاعدة الهيدروليك | F4: 3 | G4: Yes
A5: IMG-004 | B5: BC-002 | C5: Main | D5: /assets/products/barber-salon/BC-002/main.webp | E5: كرسي كوافير صالون نسائي المنظر الرئيسي | F5: 1 | G5: Yes
A6: IMG-005 | B6: BC-002 | C6: Gallery | D6: /assets/products/barber-salon/BC-002/side.webp | E6: كرسي كوافير المنظر الجانبي | F6: 2 | G6: Yes
A7: IMG-006 | B7: KC-001 | C7: Main | D7: /assets/products/kids/KC-001/main.webp | E7: كرسي حلاقة أطفال شكل سيارة باللون الأحمر | F7: 1 | G7: Yes
A8: IMG-007 | B8: KC-001 | C8: Detail | D8: /assets/products/kids/KC-001/front.webp | E8: لوحة قيادة سيارة كرسي الأطفال وعجلة القيادة | F8: 2 | G8: Yes

Sheet ProductVariants
A1: VariantID | B1: ProductID | C1: VariantName | D1: VariantType | E1: VariantValue | F1: AdditionalPrice | G1: Available | H1: ImagePath
A2: VAR-001 | B2: BC-001 | C2: لون أسود ملكي | D2: Color | E2: Black | F2: 0 | G2: Yes | H2: /assets/products/barber-salon/BC-001/black.webp
A3: VAR-002 | B3: BC-001 | C3: لون بني كابتشينو | D3: Color | E3: Brown | F3: 0 | G3: Yes | H3: /assets/products/barber-salon/BC-001/brown.webp
A4: VAR-003 | B4: BC-001 | C4: قاعدة ستانلس ذهبي فخم | D4: BaseType | E4: Gold Chrome | F4: 450 | G4: Yes | H4: /assets/products/barber-salon/BC-001/base-gold.webp
A5: VAR-004 | B5: BC-002 | C5: لون رمادي فيراني | D5: Color | E5: Grey | F5: 0 | G5: Yes | H5: /assets/products/barber-salon/BC-002/grey.webp
A6: VAR-005 | B6: KC-001 | C6: لون أحمر رياضي | D6: Color | E6: Red | F6: 0 | G6: Yes | H6: /assets/products/kids/KC-001/red.webp
A7: VAR-006 | B7: KC-001 | C7: لون أزرق ملكي | D7: Color | E7: Blue | F7: 0 | G7: Yes | H7: /assets/products/kids/KC-001/blue.webp

Sheet WebsiteSettings
A1: SettingKey | B1: SettingValue | C1: Description
A2: BusinessName | B2: مصنع أولاد يحيى لتصنيع كراسي الحلاقة | C2: الاسم الرسمي والكامل للمصنع
A3: BrandName | B3: Awlad Yahya | C3: الاسم التجاري المختصر بالإنجليزية
A4: Phone | B4: 01008355616 | C4: رقم الهاتف والاتصال المباشر لخدمة العملاء
A5: WhatsAppCatalog | B5: https://wa.me/c/201064116703 | C5: رابط كتالوج واتساب التجاري لعرض المنتجات
A6: FacebookPage | B6: https://www.facebook.com/YahiaSonsCosmetics | C6: رابط الصفحة الرسمية على فيسبوك
A7: TelegramChannel | B7: https://t.me/YahiaSons | C7: رابط قناة التليجرام لمتابعة التحديثات والعروض
A8: Currency | B8: EGP | C8: عملة التسعير المعتمدة على الموقع
A9: DefaultShowPrice | B9: Yes | C9: الحالة الافتراضية لعرض السعر في حال عدم تحديده بالمنتج
A10: AntigravityDataSourceVersion | B10: 1.0 | C10: إصدار هيكل ملف قاعدة البيانات المعتمد لنظام Antigravity
